unique_constraints_check.py module loaded
All checks passed!
unique_constraints_check.py module loaded
All checks passed!
2024-09-23 17:10:32,187 [ERROR] [no_request_id] gunicorn.error: Connection in use: ('127.0.0.1', 8000) (/Users/merwanehamadi/Library/Caches/pypoetry/virtualenvs/bluewind-5kHNo6Af-py3.12/lib/python3.12/site-packages/gunicorn/glogging.py:272)
2024-09-23 17:10:32,188 [ERROR] [no_request_id] gunicorn.error: Retrying in 1 second. (/Users/merwanehamadi/Library/Caches/pypoetry/virtualenvs/bluewind-5kHNo6Af-py3.12/lib/python3.12/site-packages/gunicorn/glogging.py:272)
2024-09-23 17:10:33,191 [ERROR] [no_request_id] gunicorn.error: Connection in use: ('127.0.0.1', 8000) (/Users/merwanehamadi/Library/Caches/pypoetry/virtualenvs/bluewind-5kHNo6Af-py3.12/lib/python3.12/site-packages/gunicorn/glogging.py:272)
2024-09-23 17:10:33,191 [ERROR] [no_request_id] gunicorn.error: Retrying in 1 second. (/Users/merwanehamadi/Library/Caches/pypoetry/virtualenvs/bluewind-5kHNo6Af-py3.12/lib/python3.12/site-packages/gunicorn/glogging.py:272)
2024-09-23 17:10:34,193 [ERROR] [no_request_id] gunicorn.error: Connection in use: ('127.0.0.1', 8000) (/Users/merwanehamadi/Library/Caches/pypoetry/virtualenvs/bluewind-5kHNo6Af-py3.12/lib/python3.12/site-packages/gunicorn/glogging.py:272)
2024-09-23 17:10:34,193 [ERROR] [no_request_id] gunicorn.error: Retrying in 1 second. (/Users/merwanehamadi/Library/Caches/pypoetry/virtualenvs/bluewind-5kHNo6Af-py3.12/lib/python3.12/site-packages/gunicorn/glogging.py:272)
2024-09-23 17:10:35,199 [ERROR] [no_request_id] gunicorn.error: Connection in use: ('127.0.0.1', 8000) (/Users/merwanehamadi/Library/Caches/pypoetry/virtualenvs/bluewind-5kHNo6Af-py3.12/lib/python3.12/site-packages/gunicorn/glogging.py:272)
2024-09-23 17:10:35,199 [ERROR] [no_request_id] gunicorn.error: Retrying in 1 second. (/Users/merwanehamadi/Library/Caches/pypoetry/virtualenvs/bluewind-5kHNo6Af-py3.12/lib/python3.12/site-packages/gunicorn/glogging.py:272)
2024-09-23 17:10:36,202 [ERROR] [no_request_id] gunicorn.error: Connection in use: ('127.0.0.1', 8000) (/Users/merwanehamadi/Library/Caches/pypoetry/virtualenvs/bluewind-5kHNo6Af-py3.12/lib/python3.12/site-packages/gunicorn/glogging.py:272)
2024-09-23 17:10:36,203 [ERROR] [no_request_id] gunicorn.error: Retrying in 1 second. (/Users/merwanehamadi/Library/Caches/pypoetry/virtualenvs/bluewind-5kHNo6Af-py3.12/lib/python3.12/site-packages/gunicorn/glogging.py:272)
2024-09-23 17:10:37,205 [ERROR] [no_request_id] gunicorn.error: Can't connect to ('127.0.0.1', 8000) (/Users/merwanehamadi/Library/Caches/pypoetry/virtualenvs/bluewind-5kHNo6Af-py3.12/lib/python3.12/site-packages/gunicorn/glogging.py:272)
unique_constraints_check.py module loaded
All checks passed!
2024-09-23 17:11:31,184 [ERROR] [no_request_id] gunicorn.error: Connection in use: ('127.0.0.1', 8000) (/Users/merwanehamadi/Library/Caches/pypoetry/virtualenvs/bluewind-5kHNo6Af-py3.12/lib/python3.12/site-packages/gunicorn/glogging.py:272)
2024-09-23 17:11:31,184 [ERROR] [no_request_id] gunicorn.error: Retrying in 1 second. (/Users/merwanehamadi/Library/Caches/pypoetry/virtualenvs/bluewind-5kHNo6Af-py3.12/lib/python3.12/site-packages/gunicorn/glogging.py:272)
2024-09-23 17:11:32,186 [ERROR] [no_request_id] gunicorn.error: Connection in use: ('127.0.0.1', 8000) (/Users/merwanehamadi/Library/Caches/pypoetry/virtualenvs/bluewind-5kHNo6Af-py3.12/lib/python3.12/site-packages/gunicorn/glogging.py:272)
2024-09-23 17:11:32,186 [ERROR] [no_request_id] gunicorn.error: Retrying in 1 second. (/Users/merwanehamadi/Library/Caches/pypoetry/virtualenvs/bluewind-5kHNo6Af-py3.12/lib/python3.12/site-packages/gunicorn/glogging.py:272)
2024-09-23 17:11:33,188 [ERROR] [no_request_id] gunicorn.error: Connection in use: ('127.0.0.1', 8000) (/Users/merwanehamadi/Library/Caches/pypoetry/virtualenvs/bluewind-5kHNo6Af-py3.12/lib/python3.12/site-packages/gunicorn/glogging.py:272)
2024-09-23 17:11:33,188 [ERROR] [no_request_id] gunicorn.error: Retrying in 1 second. (/Users/merwanehamadi/Library/Caches/pypoetry/virtualenvs/bluewind-5kHNo6Af-py3.12/lib/python3.12/site-packages/gunicorn/glogging.py:272)
2024-09-23 17:11:34,193 [ERROR] [no_request_id] gunicorn.error: Connection in use: ('127.0.0.1', 8000) (/Users/merwanehamadi/Library/Caches/pypoetry/virtualenvs/bluewind-5kHNo6Af-py3.12/lib/python3.12/site-packages/gunicorn/glogging.py:272)
2024-09-23 17:11:34,193 [ERROR] [no_request_id] gunicorn.error: Retrying in 1 second. (/Users/merwanehamadi/Library/Caches/pypoetry/virtualenvs/bluewind-5kHNo6Af-py3.12/lib/python3.12/site-packages/gunicorn/glogging.py:272)
2024-09-23 17:11:35,197 [ERROR] [no_request_id] gunicorn.error: Connection in use: ('127.0.0.1', 8000) (/Users/merwanehamadi/Library/Caches/pypoetry/virtualenvs/bluewind-5kHNo6Af-py3.12/lib/python3.12/site-packages/gunicorn/glogging.py:272)
2024-09-23 17:11:35,197 [ERROR] [no_request_id] gunicorn.error: Retrying in 1 second. (/Users/merwanehamadi/Library/Caches/pypoetry/virtualenvs/bluewind-5kHNo6Af-py3.12/lib/python3.12/site-packages/gunicorn/glogging.py:272)
2024-09-23 17:11:36,200 [ERROR] [no_request_id] gunicorn.error: Can't connect to ('127.0.0.1', 8000) (/Users/merwanehamadi/Library/Caches/pypoetry/virtualenvs/bluewind-5kHNo6Af-py3.12/lib/python3.12/site-packages/gunicorn/glogging.py:272)
unique_constraints_check.py module loaded
All checks passed!
unique_constraints_check.py module loaded
All checks passed!
unique_constraints_check.py module loaded
All checks passed!
2024-09-23 17:17:04,719 [ERROR] [no_request_id] gunicorn.error: Connection in use: ('127.0.0.1', 8000) (/Users/merwanehamadi/Library/Caches/pypoetry/virtualenvs/bluewind-5kHNo6Af-py3.12/lib/python3.12/site-packages/gunicorn/glogging.py:272)
2024-09-23 17:17:04,719 [ERROR] [no_request_id] gunicorn.error: Retrying in 1 second. (/Users/merwanehamadi/Library/Caches/pypoetry/virtualenvs/bluewind-5kHNo6Af-py3.12/lib/python3.12/site-packages/gunicorn/glogging.py:272)
2024-09-23 17:17:05,724 [ERROR] [no_request_id] gunicorn.error: Connection in use: ('127.0.0.1', 8000) (/Users/merwanehamadi/Library/Caches/pypoetry/virtualenvs/bluewind-5kHNo6Af-py3.12/lib/python3.12/site-packages/gunicorn/glogging.py:272)
2024-09-23 17:17:05,724 [ERROR] [no_request_id] gunicorn.error: Retrying in 1 second. (/Users/merwanehamadi/Library/Caches/pypoetry/virtualenvs/bluewind-5kHNo6Af-py3.12/lib/python3.12/site-packages/gunicorn/glogging.py:272)
2024-09-23 17:17:06,728 [ERROR] [no_request_id] gunicorn.error: Connection in use: ('127.0.0.1', 8000) (/Users/merwanehamadi/Library/Caches/pypoetry/virtualenvs/bluewind-5kHNo6Af-py3.12/lib/python3.12/site-packages/gunicorn/glogging.py:272)
2024-09-23 17:17:06,729 [ERROR] [no_request_id] gunicorn.error: Retrying in 1 second. (/Users/merwanehamadi/Library/Caches/pypoetry/virtualenvs/bluewind-5kHNo6Af-py3.12/lib/python3.12/site-packages/gunicorn/glogging.py:272)
2024-09-23 17:17:07,732 [ERROR] [no_request_id] gunicorn.error: Connection in use: ('127.0.0.1', 8000) (/Users/merwanehamadi/Library/Caches/pypoetry/virtualenvs/bluewind-5kHNo6Af-py3.12/lib/python3.12/site-packages/gunicorn/glogging.py:272)
2024-09-23 17:17:07,732 [ERROR] [no_request_id] gunicorn.error: Retrying in 1 second. (/Users/merwanehamadi/Library/Caches/pypoetry/virtualenvs/bluewind-5kHNo6Af-py3.12/lib/python3.12/site-packages/gunicorn/glogging.py:272)
2024-09-23 17:17:08,736 [ERROR] [no_request_id] gunicorn.error: Connection in use: ('127.0.0.1', 8000) (/Users/merwanehamadi/Library/Caches/pypoetry/virtualenvs/bluewind-5kHNo6Af-py3.12/lib/python3.12/site-packages/gunicorn/glogging.py:272)
2024-09-23 17:17:08,737 [ERROR] [no_request_id] gunicorn.error: Retrying in 1 second. (/Users/merwanehamadi/Library/Caches/pypoetry/virtualenvs/bluewind-5kHNo6Af-py3.12/lib/python3.12/site-packages/gunicorn/glogging.py:272)
2024-09-23 17:17:09,740 [ERROR] [no_request_id] gunicorn.error: Can't connect to ('127.0.0.1', 8000) (/Users/merwanehamadi/Library/Caches/pypoetry/virtualenvs/bluewind-5kHNo6Af-py3.12/lib/python3.12/site-packages/gunicorn/glogging.py:272)
unique_constraints_check.py module loaded
All checks passed!
2024-09-23 17:18:44,958 [ERROR] [no_request_id] gunicorn.error: Connection in use: ('127.0.0.1', 8000) (/Users/merwanehamadi/Library/Caches/pypoetry/virtualenvs/bluewind-5kHNo6Af-py3.12/lib/python3.12/site-packages/gunicorn/glogging.py:272)
2024-09-23 17:18:44,958 [ERROR] [no_request_id] gunicorn.error: Retrying in 1 second. (/Users/merwanehamadi/Library/Caches/pypoetry/virtualenvs/bluewind-5kHNo6Af-py3.12/lib/python3.12/site-packages/gunicorn/glogging.py:272)
2024-09-23 17:18:45,959 [ERROR] [no_request_id] gunicorn.error: Connection in use: ('127.0.0.1', 8000) (/Users/merwanehamadi/Library/Caches/pypoetry/virtualenvs/bluewind-5kHNo6Af-py3.12/lib/python3.12/site-packages/gunicorn/glogging.py:272)
2024-09-23 17:18:45,959 [ERROR] [no_request_id] gunicorn.error: Retrying in 1 second. (/Users/merwanehamadi/Library/Caches/pypoetry/virtualenvs/bluewind-5kHNo6Af-py3.12/lib/python3.12/site-packages/gunicorn/glogging.py:272)
2024-09-23 17:18:46,961 [ERROR] [no_request_id] gunicorn.error: Connection in use: ('127.0.0.1', 8000) (/Users/merwanehamadi/Library/Caches/pypoetry/virtualenvs/bluewind-5kHNo6Af-py3.12/lib/python3.12/site-packages/gunicorn/glogging.py:272)
2024-09-23 17:18:46,961 [ERROR] [no_request_id] gunicorn.error: Retrying in 1 second. (/Users/merwanehamadi/Library/Caches/pypoetry/virtualenvs/bluewind-5kHNo6Af-py3.12/lib/python3.12/site-packages/gunicorn/glogging.py:272)
2024-09-23 17:18:47,966 [ERROR] [no_request_id] gunicorn.error: Connection in use: ('127.0.0.1', 8000) (/Users/merwanehamadi/Library/Caches/pypoetry/virtualenvs/bluewind-5kHNo6Af-py3.12/lib/python3.12/site-packages/gunicorn/glogging.py:272)
2024-09-23 17:18:47,967 [ERROR] [no_request_id] gunicorn.error: Retrying in 1 second. (/Users/merwanehamadi/Library/Caches/pypoetry/virtualenvs/bluewind-5kHNo6Af-py3.12/lib/python3.12/site-packages/gunicorn/glogging.py:272)
2024-09-23 17:18:48,970 [ERROR] [no_request_id] gunicorn.error: Connection in use: ('127.0.0.1', 8000) (/Users/merwanehamadi/Library/Caches/pypoetry/virtualenvs/bluewind-5kHNo6Af-py3.12/lib/python3.12/site-packages/gunicorn/glogging.py:272)
2024-09-23 17:18:48,970 [ERROR] [no_request_id] gunicorn.error: Retrying in 1 second. (/Users/merwanehamadi/Library/Caches/pypoetry/virtualenvs/bluewind-5kHNo6Af-py3.12/lib/python3.12/site-packages/gunicorn/glogging.py:272)
2024-09-23 17:18:49,976 [ERROR] [no_request_id] gunicorn.error: Can't connect to ('127.0.0.1', 8000) (/Users/merwanehamadi/Library/Caches/pypoetry/virtualenvs/bluewind-5kHNo6Af-py3.12/lib/python3.12/site-packages/gunicorn/glogging.py:272)
unique_constraints_check.py module loaded
All checks passed!
2024-09-23 17:19:15,268 [ERROR] [no_request_id] gunicorn.error: Connection in use: ('127.0.0.1', 8000) (/Users/merwanehamadi/Library/Caches/pypoetry/virtualenvs/bluewind-5kHNo6Af-py3.12/lib/python3.12/site-packages/gunicorn/glogging.py:272)
2024-09-23 17:19:15,269 [ERROR] [no_request_id] gunicorn.error: Retrying in 1 second. (/Users/merwanehamadi/Library/Caches/pypoetry/virtualenvs/bluewind-5kHNo6Af-py3.12/lib/python3.12/site-packages/gunicorn/glogging.py:272)
2024-09-23 17:19:16,270 [ERROR] [no_request_id] gunicorn.error: Connection in use: ('127.0.0.1', 8000) (/Users/merwanehamadi/Library/Caches/pypoetry/virtualenvs/bluewind-5kHNo6Af-py3.12/lib/python3.12/site-packages/gunicorn/glogging.py:272)
2024-09-23 17:19:16,270 [ERROR] [no_request_id] gunicorn.error: Retrying in 1 second. (/Users/merwanehamadi/Library/Caches/pypoetry/virtualenvs/bluewind-5kHNo6Af-py3.12/lib/python3.12/site-packages/gunicorn/glogging.py:272)
2024-09-23 17:19:17,275 [ERROR] [no_request_id] gunicorn.error: Connection in use: ('127.0.0.1', 8000) (/Users/merwanehamadi/Library/Caches/pypoetry/virtualenvs/bluewind-5kHNo6Af-py3.12/lib/python3.12/site-packages/gunicorn/glogging.py:272)
2024-09-23 17:19:17,275 [ERROR] [no_request_id] gunicorn.error: Retrying in 1 second. (/Users/merwanehamadi/Library/Caches/pypoetry/virtualenvs/bluewind-5kHNo6Af-py3.12/lib/python3.12/site-packages/gunicorn/glogging.py:272)
2024-09-23 17:19:18,279 [ERROR] [no_request_id] gunicorn.error: Connection in use: ('127.0.0.1', 8000) (/Users/merwanehamadi/Library/Caches/pypoetry/virtualenvs/bluewind-5kHNo6Af-py3.12/lib/python3.12/site-packages/gunicorn/glogging.py:272)
2024-09-23 17:19:18,279 [ERROR] [no_request_id] gunicorn.error: Retrying in 1 second. (/Users/merwanehamadi/Library/Caches/pypoetry/virtualenvs/bluewind-5kHNo6Af-py3.12/lib/python3.12/site-packages/gunicorn/glogging.py:272)
2024-09-23 17:19:19,284 [ERROR] [no_request_id] gunicorn.error: Connection in use: ('127.0.0.1', 8000) (/Users/merwanehamadi/Library/Caches/pypoetry/virtualenvs/bluewind-5kHNo6Af-py3.12/lib/python3.12/site-packages/gunicorn/glogging.py:272)
2024-09-23 17:19:19,285 [ERROR] [no_request_id] gunicorn.error: Retrying in 1 second. (/Users/merwanehamadi/Library/Caches/pypoetry/virtualenvs/bluewind-5kHNo6Af-py3.12/lib/python3.12/site-packages/gunicorn/glogging.py:272)
2024-09-23 17:19:20,287 [ERROR] [no_request_id] gunicorn.error: Can't connect to ('127.0.0.1', 8000) (/Users/merwanehamadi/Library/Caches/pypoetry/virtualenvs/bluewind-5kHNo6Af-py3.12/lib/python3.12/site-packages/gunicorn/glogging.py:272)
unique_constraints_check.py module loaded
All checks passed!
unique_constraints_check.py module loaded
All checks passed!
2024-09-23 17:21:47,166 [ERROR] [no_request_id] gunicorn.error: Connection in use: ('127.0.0.1', 8000) (/Users/merwanehamadi/Library/Caches/pypoetry/virtualenvs/bluewind-5kHNo6Af-py3.12/lib/python3.12/site-packages/gunicorn/glogging.py:272)
2024-09-23 17:21:47,166 [ERROR] [no_request_id] gunicorn.error: Retrying in 1 second. (/Users/merwanehamadi/Library/Caches/pypoetry/virtualenvs/bluewind-5kHNo6Af-py3.12/lib/python3.12/site-packages/gunicorn/glogging.py:272)
2024-09-23 17:21:48,171 [ERROR] [no_request_id] gunicorn.error: Connection in use: ('127.0.0.1', 8000) (/Users/merwanehamadi/Library/Caches/pypoetry/virtualenvs/bluewind-5kHNo6Af-py3.12/lib/python3.12/site-packages/gunicorn/glogging.py:272)
2024-09-23 17:21:48,172 [ERROR] [no_request_id] gunicorn.error: Retrying in 1 second. (/Users/merwanehamadi/Library/Caches/pypoetry/virtualenvs/bluewind-5kHNo6Af-py3.12/lib/python3.12/site-packages/gunicorn/glogging.py:272)
2024-09-23 17:21:49,178 [ERROR] [no_request_id] gunicorn.error: Connection in use: ('127.0.0.1', 8000) (/Users/merwanehamadi/Library/Caches/pypoetry/virtualenvs/bluewind-5kHNo6Af-py3.12/lib/python3.12/site-packages/gunicorn/glogging.py:272)
2024-09-23 17:21:49,178 [ERROR] [no_request_id] gunicorn.error: Retrying in 1 second. (/Users/merwanehamadi/Library/Caches/pypoetry/virtualenvs/bluewind-5kHNo6Af-py3.12/lib/python3.12/site-packages/gunicorn/glogging.py:272)
2024-09-23 17:21:50,181 [ERROR] [no_request_id] gunicorn.error: Connection in use: ('127.0.0.1', 8000) (/Users/merwanehamadi/Library/Caches/pypoetry/virtualenvs/bluewind-5kHNo6Af-py3.12/lib/python3.12/site-packages/gunicorn/glogging.py:272)
2024-09-23 17:21:50,182 [ERROR] [no_request_id] gunicorn.error: Retrying in 1 second. (/Users/merwanehamadi/Library/Caches/pypoetry/virtualenvs/bluewind-5kHNo6Af-py3.12/lib/python3.12/site-packages/gunicorn/glogging.py:272)
2024-09-23 17:21:51,183 [ERROR] [no_request_id] gunicorn.error: Connection in use: ('127.0.0.1', 8000) (/Users/merwanehamadi/Library/Caches/pypoetry/virtualenvs/bluewind-5kHNo6Af-py3.12/lib/python3.12/site-packages/gunicorn/glogging.py:272)
2024-09-23 17:21:51,184 [ERROR] [no_request_id] gunicorn.error: Retrying in 1 second. (/Users/merwanehamadi/Library/Caches/pypoetry/virtualenvs/bluewind-5kHNo6Af-py3.12/lib/python3.12/site-packages/gunicorn/glogging.py:272)
2024-09-23 17:21:52,188 [ERROR] [no_request_id] gunicorn.error: Can't connect to ('127.0.0.1', 8000) (/Users/merwanehamadi/Library/Caches/pypoetry/virtualenvs/bluewind-5kHNo6Af-py3.12/lib/python3.12/site-packages/gunicorn/glogging.py:272)
unique_constraints_check.py module loaded
All checks passed!
2024-09-23 17:22:01,607 [ERROR] [no_request_id] gunicorn.error: Connection in use: ('127.0.0.1', 8000) (/Users/merwanehamadi/Library/Caches/pypoetry/virtualenvs/bluewind-5kHNo6Af-py3.12/lib/python3.12/site-packages/gunicorn/glogging.py:272)
2024-09-23 17:22:01,607 [ERROR] [no_request_id] gunicorn.error: Retrying in 1 second. (/Users/merwanehamadi/Library/Caches/pypoetry/virtualenvs/bluewind-5kHNo6Af-py3.12/lib/python3.12/site-packages/gunicorn/glogging.py:272)
2024-09-23 17:22:02,612 [ERROR] [no_request_id] gunicorn.error: Connection in use: ('127.0.0.1', 8000) (/Users/merwanehamadi/Library/Caches/pypoetry/virtualenvs/bluewind-5kHNo6Af-py3.12/lib/python3.12/site-packages/gunicorn/glogging.py:272)
2024-09-23 17:22:02,612 [ERROR] [no_request_id] gunicorn.error: Retrying in 1 second. (/Users/merwanehamadi/Library/Caches/pypoetry/virtualenvs/bluewind-5kHNo6Af-py3.12/lib/python3.12/site-packages/gunicorn/glogging.py:272)
2024-09-23 17:22:03,616 [ERROR] [no_request_id] gunicorn.error: Connection in use: ('127.0.0.1', 8000) (/Users/merwanehamadi/Library/Caches/pypoetry/virtualenvs/bluewind-5kHNo6Af-py3.12/lib/python3.12/site-packages/gunicorn/glogging.py:272)
2024-09-23 17:22:03,616 [ERROR] [no_request_id] gunicorn.error: Retrying in 1 second. (/Users/merwanehamadi/Library/Caches/pypoetry/virtualenvs/bluewind-5kHNo6Af-py3.12/lib/python3.12/site-packages/gunicorn/glogging.py:272)
2024-09-23 17:22:04,621 [ERROR] [no_request_id] gunicorn.error: Connection in use: ('127.0.0.1', 8000) (/Users/merwanehamadi/Library/Caches/pypoetry/virtualenvs/bluewind-5kHNo6Af-py3.12/lib/python3.12/site-packages/gunicorn/glogging.py:272)
2024-09-23 17:22:04,622 [ERROR] [no_request_id] gunicorn.error: Retrying in 1 second. (/Users/merwanehamadi/Library/Caches/pypoetry/virtualenvs/bluewind-5kHNo6Af-py3.12/lib/python3.12/site-packages/gunicorn/glogging.py:272)
2024-09-23 17:22:05,625 [ERROR] [no_request_id] gunicorn.error: Connection in use: ('127.0.0.1', 8000) (/Users/merwanehamadi/Library/Caches/pypoetry/virtualenvs/bluewind-5kHNo6Af-py3.12/lib/python3.12/site-packages/gunicorn/glogging.py:272)
2024-09-23 17:22:05,626 [ERROR] [no_request_id] gunicorn.error: Retrying in 1 second. (/Users/merwanehamadi/Library/Caches/pypoetry/virtualenvs/bluewind-5kHNo6Af-py3.12/lib/python3.12/site-packages/gunicorn/glogging.py:272)
2024-09-23 17:22:06,631 [ERROR] [no_request_id] gunicorn.error: Can't connect to ('127.0.0.1', 8000) (/Users/merwanehamadi/Library/Caches/pypoetry/virtualenvs/bluewind-5kHNo6Af-py3.12/lib/python3.12/site-packages/gunicorn/glogging.py:272)
unique_constraints_check.py module loaded
All checks passed!
unique_constraints_check.py module loaded
All checks passed!
2024-09-23 17:29:00,731 [ERROR] [no_request_id] gunicorn.error: Connection in use: ('127.0.0.1', 8000) (/Users/merwanehamadi/Library/Caches/pypoetry/virtualenvs/bluewind-5kHNo6Af-py3.12/lib/python3.12/site-packages/gunicorn/glogging.py:272)
2024-09-23 17:29:00,731 [ERROR] [no_request_id] gunicorn.error: Retrying in 1 second. (/Users/merwanehamadi/Library/Caches/pypoetry/virtualenvs/bluewind-5kHNo6Af-py3.12/lib/python3.12/site-packages/gunicorn/glogging.py:272)
2024-09-23 17:29:01,737 [ERROR] [no_request_id] gunicorn.error: Connection in use: ('127.0.0.1', 8000) (/Users/merwanehamadi/Library/Caches/pypoetry/virtualenvs/bluewind-5kHNo6Af-py3.12/lib/python3.12/site-packages/gunicorn/glogging.py:272)
2024-09-23 17:29:01,738 [ERROR] [no_request_id] gunicorn.error: Retrying in 1 second. (/Users/merwanehamadi/Library/Caches/pypoetry/virtualenvs/bluewind-5kHNo6Af-py3.12/lib/python3.12/site-packages/gunicorn/glogging.py:272)
2024-09-23 17:29:02,744 [ERROR] [no_request_id] gunicorn.error: Connection in use: ('127.0.0.1', 8000) (/Users/merwanehamadi/Library/Caches/pypoetry/virtualenvs/bluewind-5kHNo6Af-py3.12/lib/python3.12/site-packages/gunicorn/glogging.py:272)
2024-09-23 17:29:02,745 [ERROR] [no_request_id] gunicorn.error: Retrying in 1 second. (/Users/merwanehamadi/Library/Caches/pypoetry/virtualenvs/bluewind-5kHNo6Af-py3.12/lib/python3.12/site-packages/gunicorn/glogging.py:272)
2024-09-23 17:29:03,749 [ERROR] [no_request_id] gunicorn.error: Connection in use: ('127.0.0.1', 8000) (/Users/merwanehamadi/Library/Caches/pypoetry/virtualenvs/bluewind-5kHNo6Af-py3.12/lib/python3.12/site-packages/gunicorn/glogging.py:272)
2024-09-23 17:29:03,749 [ERROR] [no_request_id] gunicorn.error: Retrying in 1 second. (/Users/merwanehamadi/Library/Caches/pypoetry/virtualenvs/bluewind-5kHNo6Af-py3.12/lib/python3.12/site-packages/gunicorn/glogging.py:272)
2024-09-23 17:29:04,755 [ERROR] [no_request_id] gunicorn.error: Connection in use: ('127.0.0.1', 8000) (/Users/merwanehamadi/Library/Caches/pypoetry/virtualenvs/bluewind-5kHNo6Af-py3.12/lib/python3.12/site-packages/gunicorn/glogging.py:272)
2024-09-23 17:29:04,755 [ERROR] [no_request_id] gunicorn.error: Retrying in 1 second. (/Users/merwanehamadi/Library/Caches/pypoetry/virtualenvs/bluewind-5kHNo6Af-py3.12/lib/python3.12/site-packages/gunicorn/glogging.py:272)
unique_constraints_check.py module loaded
All checks passed!
[2024-09-23 18:06:35 +0000] [60220] [INFO] Starting gunicorn 22.0.0
[2024-09-23 18:06:35 +0000] [60220] [INFO] Listening at: http://127.0.0.1:8000 (60220)
[2024-09-23 18:06:35 +0000] [60220] [INFO] Using worker: gevent
[2024-09-23 18:06:35 +0000] [60310] [INFO] Booting worker with pid: 60310
unique_constraints_check.py module loaded
All checks passed!
[2024-09-23 18:06:53 +0000] [60485] [INFO] Starting gunicorn 22.0.0
[2024-09-23 18:06:53 +0000] [60485] [ERROR] Connection in use: ('127.0.0.1', 8000)
[2024-09-23 18:06:53 +0000] [60485] [ERROR] Retrying in 1 second.
[2024-09-23 18:06:54 +0000] [60485] [ERROR] Connection in use: ('127.0.0.1', 8000)
[2024-09-23 18:06:54 +0000] [60485] [ERROR] Retrying in 1 second.
[2024-09-23 18:06:55 +0000] [60485] [ERROR] Connection in use: ('127.0.0.1', 8000)
[2024-09-23 18:06:55 +0000] [60485] [ERROR] Retrying in 1 second.
[2024-09-23 18:06:56 +0000] [60485] [ERROR] Connection in use: ('127.0.0.1', 8000)
[2024-09-23 18:06:56 +0000] [60485] [ERROR] Retrying in 1 second.
[2024-09-23 18:06:57 +0000] [60485] [ERROR] Connection in use: ('127.0.0.1', 8000)
[2024-09-23 18:06:57 +0000] [60485] [ERROR] Retrying in 1 second.
[2024-09-23 18:06:58 +0000] [60485] [ERROR] Can't connect to ('127.0.0.1', 8000)
2024-09-23 18:06:58,644 [ERROR] [no_request_id] django.gunicorn: Error in manage.py (manage.py:51)
Traceback (most recent call last):
  File "/manage.py", line 48, in <module>
    main()
  File "/manage.py", line 43, in main
    execute_from_command_line(sys.argv)
  File "/bluewind/management/commands/rungunicorn.py", line 96, in handle
    GeventGunicornApplication(application, gunicorn_options).run()
SystemExit: 1

unique_constraints_check.py module loaded
All checks passed!
[2024-09-23 18:07:02 +0000] [60620] [INFO] Starting gunicorn 22.0.0
[2024-09-23 18:07:02 +0000] [60620] [ERROR] Connection in use: ('127.0.0.1', 8000)
[2024-09-23 18:07:02 +0000] [60620] [ERROR] Retrying in 1 second.
[2024-09-23 18:07:03 +0000] [60620] [ERROR] Connection in use: ('127.0.0.1', 8000)
[2024-09-23 18:07:03 +0000] [60620] [ERROR] Retrying in 1 second.
[2024-09-23 18:07:04 +0000] [60620] [ERROR] Connection in use: ('127.0.0.1', 8000)
[2024-09-23 18:07:04 +0000] [60620] [ERROR] Retrying in 1 second.
[2024-09-23 18:07:05 +0000] [60620] [ERROR] Connection in use: ('127.0.0.1', 8000)
[2024-09-23 18:07:05 +0000] [60620] [ERROR] Retrying in 1 second.
[2024-09-23 18:07:06 +0000] [60620] [ERROR] Connection in use: ('127.0.0.1', 8000)
[2024-09-23 18:07:06 +0000] [60620] [ERROR] Retrying in 1 second.
[2024-09-23 18:07:07 +0000] [60620] [ERROR] Can't connect to ('127.0.0.1', 8000)
2024-09-23 18:07:07,228 [ERROR] [no_request_id] django.gunicorn: Error in manage.py (manage.py:51)
Traceback (most recent call last):
  File "/manage.py", line 48, in <module>
    main()
  File "/manage.py", line 43, in main
    execute_from_command_line(sys.argv)
  File "/bluewind/management/commands/rungunicorn.py", line 96, in handle
    GeventGunicornApplication(application, gunicorn_options).run()
SystemExit: 1

unique_constraints_check.py module loaded
All checks passed!
[2024-09-23 18:07:21 +0000] [60877] [INFO] Starting gunicorn 22.0.0
[2024-09-23 18:07:21 +0000] [60877] [ERROR] Connection in use: ('127.0.0.1', 8000)
[2024-09-23 18:07:21 +0000] [60877] [ERROR] Retrying in 1 second.
[2024-09-23 18:07:22 +0000] [60877] [ERROR] Connection in use: ('127.0.0.1', 8000)
[2024-09-23 18:07:22 +0000] [60877] [ERROR] Retrying in 1 second.
[2024-09-23 18:07:23 +0000] [60877] [ERROR] Connection in use: ('127.0.0.1', 8000)
[2024-09-23 18:07:23 +0000] [60877] [ERROR] Retrying in 1 second.
[2024-09-23 18:07:24 +0000] [60877] [ERROR] Connection in use: ('127.0.0.1', 8000)
[2024-09-23 18:07:24 +0000] [60877] [ERROR] Retrying in 1 second.
[2024-09-23 18:07:25 +0000] [60877] [ERROR] Connection in use: ('127.0.0.1', 8000)
[2024-09-23 18:07:25 +0000] [60877] [ERROR] Retrying in 1 second.
[2024-09-23 18:07:27 +0000] [60877] [ERROR] Can't connect to ('127.0.0.1', 8000)
2024-09-23 18:07:27,004 [ERROR] [no_request_id] django.gunicorn: Error in manage.py (manage.py:51)
Traceback (most recent call last):
  File "/manage.py", line 48, in <module>
    main()
  File "/manage.py", line 43, in main
    execute_from_command_line(sys.argv)
  File "/bluewind/management/commands/rungunicorn.py", line 96, in handle
    GeventGunicornApplication(application, gunicorn_options).run()
SystemExit: 1

unique_constraints_check.py module loaded
All checks passed!
[2024-09-23 18:07:49 +0000] [61518] [INFO] Starting gunicorn 22.0.0
[2024-09-23 18:07:49 +0000] [61518] [INFO] Listening at: http://127.0.0.1:8000 (61518)
[2024-09-23 18:07:49 +0000] [61518] [INFO] Using worker: gevent
[2024-09-23 18:07:49 +0000] [61543] [INFO] Booting worker with pid: 61543
2024-09-23 18:08:11,659 [ERROR] [121] django.request: Internal Server Error: /workspaces/1/admin/flow_runs/flowrun/106/change/ (/Users/merwanehamadi/Library/Caches/pypoetry/virtualenvs/bluewind-5kHNo6Af-py3.12/lib/python3.12/site-packages/django/utils/log.py:248)
Traceback (most recent call last):
  File "/flow_runs/admin.py", line 34, in render
    form_module = importlib.import_module(module_name)
ModuleNotFoundError: No module named 'flows.centralize_logs.output_forms'

Traceback (most recent call last):
  File "/flow_runs/admin.py", line 34, in render
    form_module = importlib.import_module(module_name)
ModuleNotFoundError: No module named 'flows.centralize_logs.output_forms'

[2024-09-23 18:16:39 +0000] [61518] [INFO] Handling signal: int
[2024-09-23 18:16:39 +0000] [61543] [INFO] Worker exiting (pid: 61543)
2024-09-23 18:16:39,495 [ERROR] [no_request_id] django.gunicorn: Error in manage.py (manage.py:51)
Traceback (most recent call last):
  File "/manage.py", line 48, in <module>
    main()
  File "/manage.py", line 43, in main
    execute_from_command_line(sys.argv)
  File "/bluewind/management/commands/rungunicorn.py", line 96, in handle
    GeventGunicornApplication(application, gunicorn_options).run()
SystemExit: 0

[2024-09-23 18:16:39 +0000] [61518] [INFO] Shutting down: Master
2024-09-23 18:16:39,701 [ERROR] [no_request_id] django.gunicorn: Error in manage.py (manage.py:51)
Traceback (most recent call last):
  File "/manage.py", line 48, in <module>
    main()
  File "/manage.py", line 43, in main
    execute_from_command_line(sys.argv)
  File "/bluewind/management/commands/rungunicorn.py", line 96, in handle
    GeventGunicornApplication(application, gunicorn_options).run()
SystemExit: 0

unique_constraints_check.py module loaded
All checks passed!
[2024-09-23 18:16:42 +0000] [66325] [INFO] Starting gunicorn 22.0.0
[2024-09-23 18:16:42 +0000] [66325] [INFO] Listening at: http://127.0.0.1:8000 (66325)
[2024-09-23 18:16:42 +0000] [66325] [INFO] Using worker: gevent
[2024-09-23 18:16:42 +0000] [66360] [INFO] Booting worker with pid: 66360
2024-09-23 18:16:51,135 [ERROR] [124] django.request: Internal Server Error: /workspaces/1/admin/flow_runs/flowrun/106/change/ (/Users/merwanehamadi/Library/Caches/pypoetry/virtualenvs/bluewind-5kHNo6Af-py3.12/lib/python3.12/site-packages/django/utils/log.py:248)
Traceback (most recent call last):
  File "/flow_runs/admin.py", line 34, in render
    form_module = importlib.import_module(module_name)
ModuleNotFoundError: No module named 'flows.centralize_logs.output_forms'

Traceback (most recent call last):
  File "/flow_runs/admin.py", line 34, in render
    form_module = importlib.import_module(module_name)
ModuleNotFoundError: No module named 'flows.centralize_logs.output_forms'

[2024-09-23 18:18:15 +0000] [66325] [INFO] Handling signal: int
[2024-09-23 18:18:15 +0000] [66360] [INFO] Worker exiting (pid: 66360)
2024-09-23 18:18:15,962 [ERROR] [no_request_id] django.gunicorn: Error in manage.py (manage.py:51)
Traceback (most recent call last):
  File "/manage.py", line 48, in <module>
    main()
  File "/manage.py", line 43, in main
    execute_from_command_line(sys.argv)
  File "/bluewind/management/commands/rungunicorn.py", line 96, in handle
    GeventGunicornApplication(application, gunicorn_options).run()
SystemExit: 0

Traceback (most recent call last):
  File "/Users/merwanehamadi/Library/Caches/pypoetry/virtualenvs/bluewind-5kHNo6Af-py3.12/lib/python3.12/site-packages/gevent/monkey.py", line 849, in _shutdown
    sleep()
  File "/Users/merwanehamadi/Library/Caches/pypoetry/virtualenvs/bluewind-5kHNo6Af-py3.12/lib/python3.12/site-packages/gevent/hub.py", line 159, in sleep
    waiter.get()
  File "src/gevent/_waiter.py", line 143, in gevent._gevent_c_waiter.Waiter.get
  File "src/gevent/_waiter.py", line 154, in gevent._gevent_c_waiter.Waiter.get
  File "src/gevent/_greenlet_primitives.py", line 61, in gevent._gevent_c_greenlet_primitives.SwitchOutGreenletWithLoop.switch
  File "src/gevent/_greenlet_primitives.py", line 61, in gevent._gevent_c_greenlet_primitives.SwitchOutGreenletWithLoop.switch
  File "src/gevent/_greenlet_primitives.py", line 65, in gevent._gevent_c_greenlet_primitives.SwitchOutGreenletWithLoop.switch
  File "src/gevent/_gevent_c_greenlet_primitives.pxd", line 35, in gevent._gevent_c_greenlet_primitives._greenlet_switch
  File "src/gevent/greenlet.py", line 908, in gevent._gevent_cgreenlet.Greenlet.run
  File "/Users/merwanehamadi/Library/Caches/pypoetry/virtualenvs/bluewind-5kHNo6Af-py3.12/lib/python3.12/site-packages/gunicorn/workers/base.py", line 198, in handle_quit
    sys.exit(0)
SystemExit: 0
2024-09-23T18:18:15Z <greenlet.greenlet object at 0x1019e18c0 (otid=0x100d77d20) current active started main> failed with SystemExit

[2024-09-23 18:18:16 +0000] [66325] [INFO] Shutting down: Master
2024-09-23 18:18:16,176 [ERROR] [no_request_id] django.gunicorn: Error in manage.py (manage.py:51)
Traceback (most recent call last):
  File "/manage.py", line 48, in <module>
    main()
  File "/manage.py", line 43, in main
    execute_from_command_line(sys.argv)
  File "/bluewind/management/commands/rungunicorn.py", line 96, in handle
    GeventGunicornApplication(application, gunicorn_options).run()
SystemExit: 0

unique_constraints_check.py module loaded
All checks passed!
[2024-09-23 18:18:18 +0000] [67299] [INFO] Starting gunicorn 22.0.0
[2024-09-23 18:18:18 +0000] [67299] [INFO] Listening at: http://127.0.0.1:8000 (67299)
[2024-09-23 18:18:18 +0000] [67299] [INFO] Using worker: gevent
[2024-09-23 18:18:18 +0000] [67338] [INFO] Booting worker with pid: 67338
2024-09-23 18:18:18,943 [ERROR] [127] django.request: Internal Server Error: /workspaces/1/admin/flow_runs/flowrun/106/change/ (/Users/merwanehamadi/Library/Caches/pypoetry/virtualenvs/bluewind-5kHNo6Af-py3.12/lib/python3.12/site-packages/django/utils/log.py:248)
Traceback (most recent call last):
  File "/flow_runs/admin.py", line 35, in render
    FormClass = getattr(form_module, class_name)
AttributeError: module 'flows.centralize_logs.output_forms' has no attribute 'CentralizeLogsOutputForm'. Did you mean: 'CentralizeLogsForm'?

Traceback (most recent call last):
  File "/flow_runs/admin.py", line 35, in render
    FormClass = getattr(form_module, class_name)
AttributeError: module 'flows.centralize_logs.output_forms' has no attribute 'CentralizeLogsOutputForm'. Did you mean: 'CentralizeLogsForm'?

2024-09-23 18:18:19,022 [ERROR] [128] django.request: Internal Server Error: /workspaces/1/admin/flow_runs/flowrun/106/change/ (/Users/merwanehamadi/Library/Caches/pypoetry/virtualenvs/bluewind-5kHNo6Af-py3.12/lib/python3.12/site-packages/django/utils/log.py:248)
Traceback (most recent call last):
  File "/flow_runs/admin.py", line 35, in render
    FormClass = getattr(form_module, class_name)
AttributeError: module 'flows.centralize_logs.output_forms' has no attribute 'CentralizeLogsOutputForm'. Did you mean: 'CentralizeLogsForm'?

Traceback (most recent call last):
  File "/flow_runs/admin.py", line 35, in render
    FormClass = getattr(form_module, class_name)
AttributeError: module 'flows.centralize_logs.output_forms' has no attribute 'CentralizeLogsOutputForm'. Did you mean: 'CentralizeLogsForm'?

[2024-09-23 18:20:30 +0000] [67299] [INFO] Handling signal: int
[2024-09-23 18:20:30 +0000] [67338] [INFO] Worker exiting (pid: 67338)
2024-09-23 18:20:30,315 [ERROR] [no_request_id] django.gunicorn: Error in manage.py (manage.py:51)
Traceback (most recent call last):
  File "/manage.py", line 48, in <module>
    main()
  File "/manage.py", line 43, in main
    execute_from_command_line(sys.argv)
  File "/bluewind/management/commands/rungunicorn.py", line 96, in handle
    GeventGunicornApplication(application, gunicorn_options).run()
SystemExit: 0

[2024-09-23 18:20:30 +0000] [67299] [INFO] Shutting down: Master
2024-09-23 18:20:30,527 [ERROR] [no_request_id] django.gunicorn: Error in manage.py (manage.py:51)
Traceback (most recent call last):
  File "/manage.py", line 48, in <module>
    main()
  File "/manage.py", line 43, in main
    execute_from_command_line(sys.argv)
  File "/bluewind/management/commands/rungunicorn.py", line 96, in handle
    GeventGunicornApplication(application, gunicorn_options).run()
SystemExit: 0

unique_constraints_check.py module loaded
All checks passed!
[2024-09-23 18:20:33 +0000] [68756] [INFO] Starting gunicorn 22.0.0
[2024-09-23 18:20:33 +0000] [68756] [INFO] Listening at: http://127.0.0.1:8000 (68756)
[2024-09-23 18:20:33 +0000] [68756] [INFO] Using worker: gevent
[2024-09-23 18:20:33 +0000] [68774] [INFO] Booting worker with pid: 68774
[2024-09-23 18:21:32 +0000] [68756] [INFO] Handling signal: int
[2024-09-23 18:21:32 +0000] [68774] [INFO] Worker exiting (pid: 68774)
2024-09-23 18:21:32,587 [ERROR] [no_request_id] django.gunicorn: Error in manage.py (manage.py:51)
Traceback (most recent call last):
  File "/manage.py", line 48, in <module>
    main()
  File "/manage.py", line 43, in main
    execute_from_command_line(sys.argv)
  File "/bluewind/management/commands/rungunicorn.py", line 96, in handle
    GeventGunicornApplication(application, gunicorn_options).run()
SystemExit: 0

Traceback (most recent call last):
  File "/Users/merwanehamadi/Library/Caches/pypoetry/virtualenvs/bluewind-5kHNo6Af-py3.12/lib/python3.12/site-packages/gevent/monkey.py", line 849, in _shutdown
    sleep()
  File "/Users/merwanehamadi/Library/Caches/pypoetry/virtualenvs/bluewind-5kHNo6Af-py3.12/lib/python3.12/site-packages/gevent/hub.py", line 159, in sleep
    waiter.get()
  File "src/gevent/_waiter.py", line 143, in gevent._gevent_c_waiter.Waiter.get
  File "src/gevent/_waiter.py", line 154, in gevent._gevent_c_waiter.Waiter.get
  File "src/gevent/_greenlet_primitives.py", line 61, in gevent._gevent_c_greenlet_primitives.SwitchOutGreenletWithLoop.switch
  File "src/gevent/_greenlet_primitives.py", line 61, in gevent._gevent_c_greenlet_primitives.SwitchOutGreenletWithLoop.switch
  File "src/gevent/_greenlet_primitives.py", line 65, in gevent._gevent_c_greenlet_primitives.SwitchOutGreenletWithLoop.switch
  File "src/gevent/_gevent_c_greenlet_primitives.pxd", line 35, in gevent._gevent_c_greenlet_primitives._greenlet_switch
  File "src/gevent/greenlet.py", line 908, in gevent._gevent_cgreenlet.Greenlet.run
  File "/Users/merwanehamadi/Library/Caches/pypoetry/virtualenvs/bluewind-5kHNo6Af-py3.12/lib/python3.12/site-packages/gunicorn/workers/base.py", line 198, in handle_quit
    sys.exit(0)
SystemExit: 0
2024-09-23T18:21:32Z <greenlet.greenlet object at 0x1013b1240 (otid=0x1003c5530) current active started main> failed with SystemExit

[2024-09-23 18:21:32 +0000] [68756] [INFO] Shutting down: Master
2024-09-23 18:21:32,802 [ERROR] [no_request_id] django.gunicorn: Error in manage.py (manage.py:51)
Traceback (most recent call last):
  File "/manage.py", line 48, in <module>
    main()
  File "/manage.py", line 43, in main
    execute_from_command_line(sys.argv)
  File "/bluewind/management/commands/rungunicorn.py", line 96, in handle
    GeventGunicornApplication(application, gunicorn_options).run()
SystemExit: 0

unique_constraints_check.py module loaded
All checks passed!
[2024-09-23 18:21:35 +0000] [69358] [INFO] Starting gunicorn 22.0.0
[2024-09-23 18:21:35 +0000] [69358] [INFO] Listening at: http://127.0.0.1:8000 (69358)
[2024-09-23 18:21:35 +0000] [69358] [INFO] Using worker: gevent
[2024-09-23 18:21:35 +0000] [69389] [INFO] Booting worker with pid: 69389
[2024-09-23 18:22:08 +0000] [69358] [INFO] Handling signal: int
[2024-09-23 18:22:08 +0000] [69389] [INFO] Worker exiting (pid: 69389)
2024-09-23 18:22:08,454 [ERROR] [no_request_id] django.gunicorn: Error in manage.py (manage.py:51)
Traceback (most recent call last):
  File "/manage.py", line 48, in <module>
    main()
  File "/manage.py", line 43, in main
    execute_from_command_line(sys.argv)
  File "/bluewind/management/commands/rungunicorn.py", line 96, in handle
    GeventGunicornApplication(application, gunicorn_options).run()
SystemExit: 0

[2024-09-23 18:22:08 +0000] [69358] [INFO] Shutting down: Master
2024-09-23 18:22:08,597 [ERROR] [no_request_id] django.gunicorn: Error in manage.py (manage.py:51)
Traceback (most recent call last):
  File "/manage.py", line 48, in <module>
    main()
  File "/manage.py", line 43, in main
    execute_from_command_line(sys.argv)
  File "/bluewind/management/commands/rungunicorn.py", line 96, in handle
    GeventGunicornApplication(application, gunicorn_options).run()
SystemExit: 0

unique_constraints_check.py module loaded
All checks passed!
[2024-09-23 18:22:23 +0000] [69874] [INFO] Starting gunicorn 22.0.0
[2024-09-23 18:22:23 +0000] [69874] [INFO] Listening at: http://127.0.0.1:8000 (69874)
[2024-09-23 18:22:23 +0000] [69874] [INFO] Using worker: gevent
[2024-09-23 18:22:23 +0000] [69896] [INFO] Booting worker with pid: 69896
[2024-09-23 18:22:38 +0000] [69874] [INFO] Handling signal: int
[2024-09-23 18:22:38 +0000] [69896] [INFO] Worker exiting (pid: 69896)
2024-09-23 18:22:38,970 [ERROR] [no_request_id] django.gunicorn: Error in manage.py (manage.py:51)
Traceback (most recent call last):
  File "/manage.py", line 48, in <module>
    main()
  File "/manage.py", line 43, in main
    execute_from_command_line(sys.argv)
  File "/bluewind/management/commands/rungunicorn.py", line 96, in handle
    GeventGunicornApplication(application, gunicorn_options).run()
SystemExit: 0

[2024-09-23 18:22:39 +0000] [69874] [INFO] Shutting down: Master
2024-09-23 18:22:39,183 [ERROR] [no_request_id] django.gunicorn: Error in manage.py (manage.py:51)
Traceback (most recent call last):
  File "/manage.py", line 48, in <module>
    main()
  File "/manage.py", line 43, in main
    execute_from_command_line(sys.argv)
  File "/bluewind/management/commands/rungunicorn.py", line 96, in handle
    GeventGunicornApplication(application, gunicorn_options).run()
SystemExit: 0

unique_constraints_check.py module loaded
All checks passed!
[2024-09-23 18:22:41 +0000] [70102] [INFO] Starting gunicorn 22.0.0
[2024-09-23 18:22:41 +0000] [70102] [INFO] Listening at: http://127.0.0.1:8000 (70102)
[2024-09-23 18:22:41 +0000] [70102] [INFO] Using worker: gevent
[2024-09-23 18:22:41 +0000] [70131] [INFO] Booting worker with pid: 70131
[2024-09-23 18:24:39 +0000] [70102] [INFO] Handling signal: int
[2024-09-23 18:24:39 +0000] [70131] [INFO] Worker exiting (pid: 70131)
2024-09-23 18:24:39,994 [ERROR] [no_request_id] django.gunicorn: Error in manage.py (manage.py:51)
Traceback (most recent call last):
  File "/manage.py", line 48, in <module>
    main()
  File "/manage.py", line 43, in main
    execute_from_command_line(sys.argv)
  File "/bluewind/management/commands/rungunicorn.py", line 96, in handle
    GeventGunicornApplication(application, gunicorn_options).run()
SystemExit: 0

[2024-09-23 18:24:40 +0000] [70102] [INFO] Shutting down: Master
2024-09-23 18:24:40,167 [ERROR] [no_request_id] django.gunicorn: Error in manage.py (manage.py:51)
Traceback (most recent call last):
  File "/manage.py", line 48, in <module>
    main()
  File "/manage.py", line 43, in main
    execute_from_command_line(sys.argv)
  File "/bluewind/management/commands/rungunicorn.py", line 96, in handle
    GeventGunicornApplication(application, gunicorn_options).run()
SystemExit: 0

unique_constraints_check.py module loaded
All checks passed!
[2024-09-23 18:24:42 +0000] [71197] [INFO] Starting gunicorn 22.0.0
[2024-09-23 18:24:42 +0000] [71197] [INFO] Listening at: http://127.0.0.1:8000 (71197)
[2024-09-23 18:24:42 +0000] [71197] [INFO] Using worker: gevent
[2024-09-23 18:24:42 +0000] [71230] [INFO] Booting worker with pid: 71230
[2024-09-23 18:25:14 +0000] [71197] [INFO] Handling signal: int
[2024-09-23 18:25:14 +0000] [71230] [INFO] Worker exiting (pid: 71230)
2024-09-23 18:25:14,176 [ERROR] [no_request_id] django.gunicorn: Error in manage.py (manage.py:51)
Traceback (most recent call last):
  File "/manage.py", line 48, in <module>
    main()
  File "/manage.py", line 43, in main
    execute_from_command_line(sys.argv)
  File "/bluewind/management/commands/rungunicorn.py", line 96, in handle
    GeventGunicornApplication(application, gunicorn_options).run()
SystemExit: 0

Traceback (most recent call last):
  File "/Users/merwanehamadi/Library/Caches/pypoetry/virtualenvs/bluewind-5kHNo6Af-py3.12/lib/python3.12/site-packages/gevent/monkey.py", line 849, in _shutdown
    sleep()
  File "/Users/merwanehamadi/Library/Caches/pypoetry/virtualenvs/bluewind-5kHNo6Af-py3.12/lib/python3.12/site-packages/gevent/hub.py", line 159, in sleep
    waiter.get()
  File "src/gevent/_waiter.py", line 143, in gevent._gevent_c_waiter.Waiter.get
  File "src/gevent/_waiter.py", line 154, in gevent._gevent_c_waiter.Waiter.get
  File "src/gevent/_greenlet_primitives.py", line 61, in gevent._gevent_c_greenlet_primitives.SwitchOutGreenletWithLoop.switch
  File "src/gevent/_greenlet_primitives.py", line 61, in gevent._gevent_c_greenlet_primitives.SwitchOutGreenletWithLoop.switch
  File "src/gevent/_greenlet_primitives.py", line 65, in gevent._gevent_c_greenlet_primitives.SwitchOutGreenletWithLoop.switch
  File "src/gevent/_gevent_c_greenlet_primitives.pxd", line 35, in gevent._gevent_c_greenlet_primitives._greenlet_switch
  File "src/gevent/greenlet.py", line 908, in gevent._gevent_cgreenlet.Greenlet.run
  File "/Users/merwanehamadi/Library/Caches/pypoetry/virtualenvs/bluewind-5kHNo6Af-py3.12/lib/python3.12/site-packages/gunicorn/workers/base.py", line 198, in handle_quit
    sys.exit(0)
SystemExit: 0
2024-09-23T18:25:14Z <greenlet.greenlet object at 0x105271240 (otid=0x105217cf0) current active started main> failed with SystemExit

[2024-09-23 18:25:14 +0000] [71197] [INFO] Shutting down: Master
2024-09-23 18:25:14,388 [ERROR] [no_request_id] django.gunicorn: Error in manage.py (manage.py:51)
Traceback (most recent call last):
  File "/manage.py", line 48, in <module>
    main()
  File "/manage.py", line 43, in main
    execute_from_command_line(sys.argv)
  File "/bluewind/management/commands/rungunicorn.py", line 96, in handle
    GeventGunicornApplication(application, gunicorn_options).run()
SystemExit: 0

unique_constraints_check.py module loaded
All checks passed!
[2024-09-23 18:25:20 +0000] [71708] [INFO] Starting gunicorn 22.0.0
[2024-09-23 18:25:20 +0000] [71708] [INFO] Listening at: http://127.0.0.1:8000 (71708)
[2024-09-23 18:25:20 +0000] [71708] [INFO] Using worker: gevent
[2024-09-23 18:25:20 +0000] [71736] [INFO] Booting worker with pid: 71736
[2024-09-23 18:29:45 +0000] [71708] [INFO] Handling signal: winch
[2024-09-23 18:33:48 +0000] [71708] [INFO] Handling signal: int
[2024-09-23 18:33:48 +0000] [71736] [INFO] Worker exiting (pid: 71736)
2024-09-23 18:33:48,239 [ERROR] [no_request_id] django.gunicorn: Error in manage.py (manage.py:51)
Traceback (most recent call last):
  File "/manage.py", line 48, in <module>
    main()
  File "/manage.py", line 43, in main
    execute_from_command_line(sys.argv)
  File "/bluewind/management/commands/rungunicorn.py", line 96, in handle
    GeventGunicornApplication(application, gunicorn_options).run()
SystemExit: 0

Traceback (most recent call last):
  File "/Users/merwanehamadi/Library/Caches/pypoetry/virtualenvs/bluewind-5kHNo6Af-py3.12/lib/python3.12/site-packages/gevent/monkey.py", line 849, in _shutdown
    sleep()
  File "/Users/merwanehamadi/Library/Caches/pypoetry/virtualenvs/bluewind-5kHNo6Af-py3.12/lib/python3.12/site-packages/gevent/hub.py", line 159, in sleep
    waiter.get()
  File "src/gevent/_waiter.py", line 143, in gevent._gevent_c_waiter.Waiter.get
  File "src/gevent/_waiter.py", line 154, in gevent._gevent_c_waiter.Waiter.get
  File "src/gevent/_greenlet_primitives.py", line 61, in gevent._gevent_c_greenlet_primitives.SwitchOutGreenletWithLoop.switch
  File "src/gevent/_greenlet_primitives.py", line 61, in gevent._gevent_c_greenlet_primitives.SwitchOutGreenletWithLoop.switch
  File "src/gevent/_greenlet_primitives.py", line 65, in gevent._gevent_c_greenlet_primitives.SwitchOutGreenletWithLoop.switch
  File "src/gevent/_gevent_c_greenlet_primitives.pxd", line 35, in gevent._gevent_c_greenlet_primitives._greenlet_switch
  File "src/gevent/greenlet.py", line 908, in gevent._gevent_cgreenlet.Greenlet.run
  File "/Users/merwanehamadi/Library/Caches/pypoetry/virtualenvs/bluewind-5kHNo6Af-py3.12/lib/python3.12/site-packages/gunicorn/workers/base.py", line 198, in handle_quit
    sys.exit(0)
SystemExit: 0
2024-09-23T18:33:48Z <greenlet.greenlet object at 0x10229e9c0 (otid=0x101898210) current active started main> failed with SystemExit

[2024-09-23 18:33:48 +0000] [71708] [INFO] Shutting down: Master
2024-09-23 18:33:48,454 [ERROR] [no_request_id] django.gunicorn: Error in manage.py (manage.py:51)
Traceback (most recent call last):
  File "/manage.py", line 48, in <module>
    main()
  File "/manage.py", line 43, in main
    execute_from_command_line(sys.argv)
  File "/bluewind/management/commands/rungunicorn.py", line 96, in handle
    GeventGunicornApplication(application, gunicorn_options).run()
SystemExit: 0

unique_constraints_check.py module loaded
All checks passed!
[2024-09-23 18:33:51 +0000] [76137] [INFO] Starting gunicorn 22.0.0
[2024-09-23 18:33:51 +0000] [76137] [INFO] Listening at: http://127.0.0.1:8000 (76137)
[2024-09-23 18:33:51 +0000] [76137] [INFO] Using worker: gevent
[2024-09-23 18:33:51 +0000] [76164] [INFO] Booting worker with pid: 76164
[2024-09-23 18:34:00 +0000] [76137] [INFO] Handling signal: int
[2024-09-23 18:34:00 +0000] [76164] [INFO] Worker exiting (pid: 76164)
2024-09-23 18:34:00,914 [ERROR] [no_request_id] django.gunicorn: Error in manage.py (manage.py:51)
Traceback (most recent call last):
  File "/manage.py", line 48, in <module>
    main()
  File "/manage.py", line 43, in main
    execute_from_command_line(sys.argv)
  File "/bluewind/management/commands/rungunicorn.py", line 96, in handle
    GeventGunicornApplication(application, gunicorn_options).run()
SystemExit: 0

[2024-09-23 18:34:01 +0000] [76137] [INFO] Shutting down: Master
2024-09-23 18:34:01,121 [ERROR] [no_request_id] django.gunicorn: Error in manage.py (manage.py:51)
Traceback (most recent call last):
  File "/manage.py", line 48, in <module>
    main()
  File "/manage.py", line 43, in main
    execute_from_command_line(sys.argv)
  File "/bluewind/management/commands/rungunicorn.py", line 96, in handle
    GeventGunicornApplication(application, gunicorn_options).run()
SystemExit: 0

unique_constraints_check.py module loaded
All checks passed!
[2024-09-23 18:34:03 +0000] [76319] [INFO] Starting gunicorn 22.0.0
[2024-09-23 18:34:03 +0000] [76319] [INFO] Listening at: http://127.0.0.1:8000 (76319)
[2024-09-23 18:34:03 +0000] [76319] [INFO] Using worker: gevent
[2024-09-23 18:34:03 +0000] [76351] [INFO] Booting worker with pid: 76351
2024-09-23 18:34:04,118 [ERROR] [683] django.request: Internal Server Error: /workspaces/1/admin/flow_runs/flowrun/232/change/ (/Users/merwanehamadi/Library/Caches/pypoetry/virtualenvs/bluewind-5kHNo6Af-py3.12/lib/python3.12/site-packages/django/utils/log.py:248)
Traceback (most recent call last):
django.template.exceptions.TemplateSyntaxError: Could not parse the remainder: ' action.title' from 'cdscds action.title'

Traceback (most recent call last):
django.template.exceptions.TemplateSyntaxError: Could not parse the remainder: ' action.title' from 'cdscds action.title'

[2024-09-23 18:35:03 +0000] [76319] [INFO] Handling signal: int
[2024-09-23 18:35:03 +0000] [76351] [INFO] Worker exiting (pid: 76351)
2024-09-23 18:35:03,467 [ERROR] [no_request_id] django.gunicorn: Error in manage.py (manage.py:51)
Traceback (most recent call last):
  File "/manage.py", line 48, in <module>
    main()
  File "/manage.py", line 43, in main
    execute_from_command_line(sys.argv)
  File "/bluewind/management/commands/rungunicorn.py", line 96, in handle
    GeventGunicornApplication(application, gunicorn_options).run()
SystemExit: 0

[2024-09-23 18:35:03 +0000] [76319] [INFO] Shutting down: Master
2024-09-23 18:35:03,682 [ERROR] [no_request_id] django.gunicorn: Error in manage.py (manage.py:51)
Traceback (most recent call last):
  File "/manage.py", line 48, in <module>
    main()
  File "/manage.py", line 43, in main
    execute_from_command_line(sys.argv)
  File "/bluewind/management/commands/rungunicorn.py", line 96, in handle
    GeventGunicornApplication(application, gunicorn_options).run()
SystemExit: 0

unique_constraints_check.py module loaded
All checks passed!
[2024-09-23 18:35:06 +0000] [76940] [INFO] Starting gunicorn 22.0.0
[2024-09-23 18:35:06 +0000] [76940] [INFO] Listening at: http://127.0.0.1:8000 (76940)
[2024-09-23 18:35:06 +0000] [76940] [INFO] Using worker: gevent
[2024-09-23 18:35:06 +0000] [76963] [INFO] Booting worker with pid: 76963
[2024-09-23 18:40:09 +0000] [76940] [INFO] Handling signal: int
[2024-09-23 18:40:09 +0000] [76963] [INFO] Worker exiting (pid: 76963)
2024-09-23 18:40:09,542 [ERROR] [no_request_id] django.gunicorn: Error in manage.py (manage.py:51)
Traceback (most recent call last):
  File "/manage.py", line 48, in <module>
    main()
  File "/manage.py", line 43, in main
    execute_from_command_line(sys.argv)
  File "/bluewind/management/commands/rungunicorn.py", line 96, in handle
    GeventGunicornApplication(application, gunicorn_options).run()
SystemExit: 0

[2024-09-23 18:40:09 +0000] [76940] [INFO] Shutting down: Master
2024-09-23 18:40:09,757 [ERROR] [no_request_id] django.gunicorn: Error in manage.py (manage.py:51)
Traceback (most recent call last):
  File "/manage.py", line 48, in <module>
    main()
  File "/manage.py", line 43, in main
    execute_from_command_line(sys.argv)
  File "/bluewind/management/commands/rungunicorn.py", line 96, in handle
    GeventGunicornApplication(application, gunicorn_options).run()
SystemExit: 0

unique_constraints_check.py module loaded
All checks passed!
[2024-09-23 18:40:12 +0000] [79563] [INFO] Starting gunicorn 22.0.0
[2024-09-23 18:40:12 +0000] [79563] [INFO] Listening at: http://127.0.0.1:8000 (79563)
[2024-09-23 18:40:12 +0000] [79563] [INFO] Using worker: gevent
[2024-09-23 18:40:12 +0000] [79592] [INFO] Booting worker with pid: 79592
[2024-09-23 18:41:59 +0000] [79563] [INFO] Handling signal: int
[2024-09-23 18:41:59 +0000] [79592] [INFO] Worker exiting (pid: 79592)
2024-09-23 18:41:59,458 [ERROR] [no_request_id] django.gunicorn: Error in manage.py (manage.py:51)
Traceback (most recent call last):
  File "/manage.py", line 48, in <module>
    main()
  File "/manage.py", line 43, in main
    execute_from_command_line(sys.argv)
  File "/bluewind/management/commands/rungunicorn.py", line 96, in handle
    GeventGunicornApplication(application, gunicorn_options).run()
SystemExit: 0

[2024-09-23 18:41:59 +0000] [79563] [INFO] Shutting down: Master
2024-09-23 18:41:59,644 [ERROR] [no_request_id] django.gunicorn: Error in manage.py (manage.py:51)
Traceback (most recent call last):
  File "/manage.py", line 48, in <module>
    main()
  File "/manage.py", line 43, in main
    execute_from_command_line(sys.argv)
  File "/bluewind/management/commands/rungunicorn.py", line 96, in handle
    GeventGunicornApplication(application, gunicorn_options).run()
SystemExit: 0

unique_constraints_check.py module loaded
All checks passed!
[2024-09-23 18:42:02 +0000] [80573] [INFO] Starting gunicorn 22.0.0
[2024-09-23 18:42:02 +0000] [80573] [INFO] Listening at: http://127.0.0.1:8000 (80573)
[2024-09-23 18:42:02 +0000] [80573] [INFO] Using worker: gevent
[2024-09-23 18:42:02 +0000] [80600] [INFO] Booting worker with pid: 80600
[2024-09-23 18:42:44 +0000] [80573] [INFO] Handling signal: int
[2024-09-23 18:42:44 +0000] [80600] [INFO] Worker exiting (pid: 80600)
2024-09-23 18:42:44,122 [ERROR] [no_request_id] django.gunicorn: Error in manage.py (manage.py:51)
Traceback (most recent call last):
  File "/manage.py", line 48, in <module>
    main()
  File "/manage.py", line 43, in main
    execute_from_command_line(sys.argv)
  File "/bluewind/management/commands/rungunicorn.py", line 96, in handle
    GeventGunicornApplication(application, gunicorn_options).run()
SystemExit: 0

[2024-09-23 18:42:44 +0000] [80573] [INFO] Shutting down: Master
2024-09-23 18:42:44,326 [ERROR] [no_request_id] django.gunicorn: Error in manage.py (manage.py:51)
Traceback (most recent call last):
  File "/manage.py", line 48, in <module>
    main()
  File "/manage.py", line 43, in main
    execute_from_command_line(sys.argv)
  File "/bluewind/management/commands/rungunicorn.py", line 96, in handle
    GeventGunicornApplication(application, gunicorn_options).run()
SystemExit: 0

unique_constraints_check.py module loaded
All checks passed!
[2024-09-23 18:43:41 +0000] [81711] [INFO] Starting gunicorn 22.0.0
[2024-09-23 18:43:41 +0000] [81711] [INFO] Listening at: http://127.0.0.1:8000 (81711)
[2024-09-23 18:43:41 +0000] [81711] [INFO] Using worker: gevent
[2024-09-23 18:43:41 +0000] [81736] [INFO] Booting worker with pid: 81736
[2024-09-23 18:44:00 +0000] [81711] [INFO] Handling signal: int
[2024-09-23 18:44:00 +0000] [81736] [INFO] Worker exiting (pid: 81736)
2024-09-23 18:44:00,545 [ERROR] [no_request_id] django.gunicorn: Error in manage.py (manage.py:51)
Traceback (most recent call last):
  File "/manage.py", line 48, in <module>
    main()
  File "/manage.py", line 43, in main
    execute_from_command_line(sys.argv)
  File "/bluewind/management/commands/rungunicorn.py", line 96, in handle
    GeventGunicornApplication(application, gunicorn_options).run()
SystemExit: 0

[2024-09-23 18:44:00 +0000] [81711] [INFO] Shutting down: Master
2024-09-23 18:44:00,760 [ERROR] [no_request_id] django.gunicorn: Error in manage.py (manage.py:51)
Traceback (most recent call last):
  File "/manage.py", line 48, in <module>
    main()
  File "/manage.py", line 43, in main
    execute_from_command_line(sys.argv)
  File "/bluewind/management/commands/rungunicorn.py", line 96, in handle
    GeventGunicornApplication(application, gunicorn_options).run()
SystemExit: 0

unique_constraints_check.py module loaded
All checks passed!
[2024-09-23 18:44:14 +0000] [82186] [INFO] Starting gunicorn 22.0.0
[2024-09-23 18:44:14 +0000] [82186] [INFO] Listening at: http://127.0.0.1:8000 (82186)
[2024-09-23 18:44:14 +0000] [82186] [INFO] Using worker: gevent
[2024-09-23 18:44:14 +0000] [82212] [INFO] Booting worker with pid: 82212
[2024-09-23 18:44:55 +0000] [82186] [INFO] Handling signal: int
[2024-09-23 18:44:55 +0000] [82212] [INFO] Worker exiting (pid: 82212)
2024-09-23 18:44:55,962 [ERROR] [no_request_id] django.gunicorn: Error in manage.py (manage.py:51)
Traceback (most recent call last):
  File "/manage.py", line 48, in <module>
    main()
  File "/manage.py", line 43, in main
    execute_from_command_line(sys.argv)
  File "/bluewind/management/commands/rungunicorn.py", line 96, in handle
    GeventGunicornApplication(application, gunicorn_options).run()
SystemExit: 0

[2024-09-23 18:44:56 +0000] [82186] [INFO] Shutting down: Master
2024-09-23 18:44:56,173 [ERROR] [no_request_id] django.gunicorn: Error in manage.py (manage.py:51)
Traceback (most recent call last):
  File "/manage.py", line 48, in <module>
    main()
  File "/manage.py", line 43, in main
    execute_from_command_line(sys.argv)
  File "/bluewind/management/commands/rungunicorn.py", line 96, in handle
    GeventGunicornApplication(application, gunicorn_options).run()
SystemExit: 0

unique_constraints_check.py module loaded
All checks passed!
[2024-09-23 18:44:58 +0000] [82688] [INFO] Starting gunicorn 22.0.0
[2024-09-23 18:44:58 +0000] [82688] [INFO] Listening at: http://127.0.0.1:8000 (82688)
[2024-09-23 18:44:58 +0000] [82688] [INFO] Using worker: gevent
[2024-09-23 18:44:58 +0000] [82716] [INFO] Booting worker with pid: 82716
[2024-09-23 18:47:58 +0000] [82688] [INFO] Handling signal: int
[2024-09-23 18:47:58 +0000] [82716] [INFO] Worker exiting (pid: 82716)
2024-09-23 18:47:58,945 [ERROR] [no_request_id] django.gunicorn: Error in manage.py (manage.py:51)
Traceback (most recent call last):
  File "/manage.py", line 48, in <module>
    main()
  File "/manage.py", line 43, in main
    execute_from_command_line(sys.argv)
  File "/bluewind/management/commands/rungunicorn.py", line 96, in handle
    GeventGunicornApplication(application, gunicorn_options).run()
SystemExit: 0

Traceback (most recent call last):
  File "/Users/merwanehamadi/Library/Caches/pypoetry/virtualenvs/bluewind-5kHNo6Af-py3.12/lib/python3.12/site-packages/gevent/monkey.py", line 849, in _shutdown
    sleep()
  File "/Users/merwanehamadi/Library/Caches/pypoetry/virtualenvs/bluewind-5kHNo6Af-py3.12/lib/python3.12/site-packages/gevent/hub.py", line 159, in sleep
    waiter.get()
  File "src/gevent/_waiter.py", line 143, in gevent._gevent_c_waiter.Waiter.get
  File "src/gevent/_waiter.py", line 154, in gevent._gevent_c_waiter.Waiter.get
  File "src/gevent/_greenlet_primitives.py", line 61, in gevent._gevent_c_greenlet_primitives.SwitchOutGreenletWithLoop.switch
  File "src/gevent/_greenlet_primitives.py", line 61, in gevent._gevent_c_greenlet_primitives.SwitchOutGreenletWithLoop.switch
  File "src/gevent/_greenlet_primitives.py", line 65, in gevent._gevent_c_greenlet_primitives.SwitchOutGreenletWithLoop.switch
  File "src/gevent/_gevent_c_greenlet_primitives.pxd", line 35, in gevent._gevent_c_greenlet_primitives._greenlet_switch
  File "src/gevent/greenlet.py", line 908, in gevent._gevent_cgreenlet.Greenlet.run
  File "/Users/merwanehamadi/Library/Caches/pypoetry/virtualenvs/bluewind-5kHNo6Af-py3.12/lib/python3.12/site-packages/gunicorn/workers/base.py", line 198, in handle_quit
    sys.exit(0)
SystemExit: 0
2024-09-23T18:47:58Z <greenlet.greenlet object at 0x101b91240 (otid=0x101b37cf0) current active started main> failed with SystemExit

[2024-09-23 18:47:59 +0000] [82688] [INFO] Shutting down: Master
2024-09-23 18:47:59,156 [ERROR] [no_request_id] django.gunicorn: Error in manage.py (manage.py:51)
Traceback (most recent call last):
  File "/manage.py", line 48, in <module>
    main()
  File "/manage.py", line 43, in main
    execute_from_command_line(sys.argv)
  File "/bluewind/management/commands/rungunicorn.py", line 96, in handle
    GeventGunicornApplication(application, gunicorn_options).run()
SystemExit: 0

unique_constraints_check.py module loaded
All checks passed!
[2024-09-23 18:49:10 +0000] [84954] [INFO] Starting gunicorn 22.0.0
[2024-09-23 18:49:10 +0000] [84954] [INFO] Listening at: http://127.0.0.1:8000 (84954)
[2024-09-23 18:49:10 +0000] [84954] [INFO] Using worker: gevent
[2024-09-23 18:49:10 +0000] [84977] [INFO] Booting worker with pid: 84977
